<?xml version="1.0"?>
<!--
Lab 4: URDF Basics - Solution
A complete 2-DOF robotic arm URDF
-->
<robot name="simple_arm">

  <!-- Materials -->
  <material name="gray">
    <color rgba="0.5 0.5 0.5 1.0"/>
  </material>
  <material name="blue">
    <color rgba="0.2 0.2 0.8 1.0"/>
  </material>
  <material name="green">
    <color rgba="0.2 0.8 0.2 1.0"/>
  </material>
  <material name="red">
    <color rgba="0.8 0.2 0.2 1.0"/>
  </material>

  <!-- Base Link -->
  <link name="base_link">
    <visual>
      <geometry>
        <box size="0.1 0.1 0.05"/>
      </geometry>
      <material name="gray"/>
    </visual>
    <collision>
      <geometry>
        <box size="0.1 0.1 0.05"/>
      </geometry>
    </collision>
    <inertial>
      <mass value="1.0"/>
      <inertia ixx="0.001" ixy="0" ixz="0"
               iyy="0.001" iyz="0" izz="0.001"/>
    </inertial>
  </link>

  <!-- Shoulder Joint -->
  <joint name="shoulder" type="revolute">
    <parent link="base_link"/>
    <child link="upper_arm"/>
    <origin xyz="0 0 0.05" rpy="0 0 0"/>
    <axis xyz="0 1 0"/>
    <limit lower="-1.57" upper="1.57" effort="10" velocity="1.0"/>
  </joint>

  <!-- Upper Arm Link -->
  <link name="upper_arm">
    <visual>
      <origin xyz="0 0 0.15" rpy="0 0 0"/>
      <geometry>
        <cylinder radius="0.02" length="0.3"/>
      </geometry>
      <material name="blue"/>
    </visual>
    <collision>
      <origin xyz="0 0 0.15" rpy="0 0 0"/>
      <geometry>
        <cylinder radius="0.02" length="0.3"/>
      </geometry>
    </collision>
    <inertial>
      <mass value="0.5"/>
      <origin xyz="0 0 0.15"/>
      <inertia ixx="0.001" ixy="0" ixz="0"
               iyy="0.001" iyz="0" izz="0.0001"/>
    </inertial>
  </link>

  <!-- Elbow Joint -->
  <joint name="elbow" type="revolute">
    <parent link="upper_arm"/>
    <child link="lower_arm"/>
    <origin xyz="0 0 0.3" rpy="0 0 0"/>
    <axis xyz="0 1 0"/>
    <limit lower="0" upper="2.35" effort="10" velocity="1.0"/>
  </joint>

  <!-- Lower Arm Link -->
  <link name="lower_arm">
    <visual>
      <origin xyz="0 0 0.1" rpy="0 0 0"/>
      <geometry>
        <cylinder radius="0.015" length="0.2"/>
      </geometry>
      <material name="green"/>
    </visual>
    <collision>
      <origin xyz="0 0 0.1" rpy="0 0 0"/>
      <geometry>
        <cylinder radius="0.015" length="0.2"/>
      </geometry>
    </collision>
    <inertial>
      <mass value="0.3"/>
      <origin xyz="0 0 0.1"/>
      <inertia ixx="0.0005" ixy="0" ixz="0"
               iyy="0.0005" iyz="0" izz="0.0001"/>
    </inertial>
  </link>

  <!-- Wrist Joint (Fixed) -->
  <joint name="wrist" type="fixed">
    <parent link="lower_arm"/>
    <child link="end_effector"/>
    <origin xyz="0 0 0.2" rpy="0 0 0"/>
  </joint>

  <!-- End Effector Link -->
  <link name="end_effector">
    <visual>
      <geometry>
        <sphere radius="0.02"/>
      </geometry>
      <material name="red"/>
    </visual>
    <collision>
      <geometry>
        <sphere radius="0.02"/>
      </geometry>
    </collision>
    <inertial>
      <mass value="0.1"/>
      <inertia ixx="0.00001" ixy="0" ixz="0"
               iyy="0.00001" iyz="0" izz="0.00001"/>
    </inertial>
  </link>

</robot>
